[2024-02-03T03:38:01.611+0400] {taskinstance.py:1956} INFO - Dependencies all met for dep_context=non-requeueable deps ti=<TaskInstance: iris_score.prepare_data manual__2024-02-02T23:37:55.709158+00:00 [queued]>
[2024-02-03T03:38:01.615+0400] {taskinstance.py:1956} INFO - Dependencies all met for dep_context=requeueable deps ti=<TaskInstance: iris_score.prepare_data manual__2024-02-02T23:37:55.709158+00:00 [queued]>
[2024-02-03T03:38:01.616+0400] {taskinstance.py:2170} INFO - Starting attempt 1 of 2
[2024-02-03T03:38:01.625+0400] {taskinstance.py:2191} INFO - Executing <Task(BashOperator): prepare_data> on 2024-02-02 23:37:55.709158+00:00
[2024-02-03T03:38:01.628+0400] {standard_task_runner.py:60} INFO - Started process 32049 to run task
[2024-02-03T03:38:01.630+0400] {standard_task_runner.py:87} INFO - Running: ['airflow', 'tasks', 'run', 'iris_score', 'prepare_data', 'manual__2024-02-02T23:37:55.709158+00:00', '--job-id', '28', '--raw', '--subdir', 'DAGS_FOLDER/iris_score.py', '--cfg-path', '/tmp/tmpnw2kymk1']
[2024-02-03T03:38:01.631+0400] {standard_task_runner.py:88} INFO - Job 28: Subtask prepare_data
[2024-02-03T03:38:01.657+0400] {task_command.py:423} INFO - Running <TaskInstance: iris_score.prepare_data manual__2024-02-02T23:37:55.709158+00:00 [running]> on host WIN-IO5IBOGGQDO.localdomain
[2024-02-03T03:38:01.693+0400] {taskinstance.py:2480} INFO - Exporting env vars: AIRFLOW_CTX_DAG_OWNER='admin' AIRFLOW_CTX_DAG_ID='iris_score' AIRFLOW_CTX_TASK_ID='prepare_data' AIRFLOW_CTX_EXECUTION_DATE='2024-02-02T23:37:55.709158+00:00' AIRFLOW_CTX_TRY_NUMBER='1' AIRFLOW_CTX_DAG_RUN_ID='manual__2024-02-02T23:37:55.709158+00:00'
[2024-02-03T03:38:01.695+0400] {subprocess.py:63} INFO - Tmp dir root location: /tmp
[2024-02-03T03:38:01.695+0400] {subprocess.py:75} INFO - Running command: ['/usr/bin/bash', '-c', 'python3 /home/reurairin/projects/urfu/urfu_3s_mlops-3/scripts/preprocess_data.py']
[2024-02-03T03:38:01.700+0400] {subprocess.py:86} INFO - Output:
[2024-02-03T03:38:02.834+0400] {subprocess.py:93} INFO - 2024/02/03 03:38:02 INFO mlflow.tracking.fluent: Experiment with name 'preprocess_data' does not exist. Creating a new experiment.
[2024-02-03T03:38:02.968+0400] {subprocess.py:93} INFO - Traceback (most recent call last):
[2024-02-03T03:38:02.968+0400] {subprocess.py:93} INFO -   File "/home/reurairin/projects/urfu/urfu_3s_mlops-3/scripts/preprocess_data.py", line 26, in <module>
[2024-02-03T03:38:02.968+0400] {subprocess.py:93} INFO -     mlflow.end
[2024-02-03T03:38:02.968+0400] {subprocess.py:93} INFO - AttributeError: module 'mlflow' has no attribute 'end'
[2024-02-03T03:38:03.162+0400] {subprocess.py:97} INFO - Command exited with return code 1
[2024-02-03T03:38:03.166+0400] {taskinstance.py:2698} ERROR - Task failed with exception
Traceback (most recent call last):
  File "/home/reurairin/projects/urfu/urfu_3s_mlops-3/env/lib/python3.10/site-packages/airflow/models/taskinstance.py", line 433, in _execute_task
    result = execute_callable(context=context, **execute_callable_kwargs)
  File "/home/reurairin/projects/urfu/urfu_3s_mlops-3/env/lib/python3.10/site-packages/airflow/operators/bash.py", line 212, in execute
    raise AirflowException(
airflow.exceptions.AirflowException: Bash command failed. The command returned a non-zero exit code 1.
[2024-02-03T03:38:03.168+0400] {taskinstance.py:1138} INFO - Marking task as UP_FOR_RETRY. dag_id=iris_score, task_id=prepare_data, execution_date=20240202T233755, start_date=20240202T233801, end_date=20240202T233803
[2024-02-03T03:38:03.176+0400] {standard_task_runner.py:107} ERROR - Failed to execute job 28 for task prepare_data (Bash command failed. The command returned a non-zero exit code 1.; 32049)
[2024-02-03T03:38:03.206+0400] {local_task_job_runner.py:234} INFO - Task exited with return code 1
[2024-02-03T03:38:03.221+0400] {taskinstance.py:3280} INFO - 0 downstream tasks scheduled from follow-on schedule check
