[2024-02-03T03:15:50.194+0400] {taskinstance.py:1956} INFO - Dependencies all met for dep_context=non-requeueable deps ti=<TaskInstance: iris_score.get_data manual__2024-02-02T23:08:45.632214+00:00 [queued]>
[2024-02-03T03:15:50.197+0400] {taskinstance.py:1956} INFO - Dependencies all met for dep_context=requeueable deps ti=<TaskInstance: iris_score.get_data manual__2024-02-02T23:08:45.632214+00:00 [queued]>
[2024-02-03T03:15:50.198+0400] {taskinstance.py:2170} INFO - Starting attempt 2 of 2
[2024-02-03T03:15:50.209+0400] {taskinstance.py:2191} INFO - Executing <Task(BashOperator): get_data> on 2024-02-02 23:08:45.632214+00:00
[2024-02-03T03:15:50.212+0400] {standard_task_runner.py:60} INFO - Started process 26099 to run task
[2024-02-03T03:15:50.214+0400] {standard_task_runner.py:87} INFO - Running: ['airflow', 'tasks', 'run', 'iris_score', 'get_data', 'manual__2024-02-02T23:08:45.632214+00:00', '--job-id', '22', '--raw', '--subdir', 'DAGS_FOLDER/iris_score.py', '--cfg-path', '/tmp/tmp9c8y7em4']
[2024-02-03T03:15:50.214+0400] {standard_task_runner.py:88} INFO - Job 22: Subtask get_data
[2024-02-03T03:15:50.238+0400] {task_command.py:423} INFO - Running <TaskInstance: iris_score.get_data manual__2024-02-02T23:08:45.632214+00:00 [running]> on host WIN-IO5IBOGGQDO.localdomain
[2024-02-03T03:15:50.267+0400] {taskinstance.py:2480} INFO - Exporting env vars: AIRFLOW_CTX_DAG_OWNER='admin' AIRFLOW_CTX_DAG_ID='iris_score' AIRFLOW_CTX_TASK_ID='get_data' AIRFLOW_CTX_EXECUTION_DATE='2024-02-02T23:08:45.632214+00:00' AIRFLOW_CTX_TRY_NUMBER='2' AIRFLOW_CTX_DAG_RUN_ID='manual__2024-02-02T23:08:45.632214+00:00'
[2024-02-03T03:15:50.268+0400] {subprocess.py:63} INFO - Tmp dir root location: /tmp
[2024-02-03T03:15:50.268+0400] {subprocess.py:75} INFO - Running command: ['/usr/bin/bash', '-c', 'python3 /home/reurairin/projects/urfu/urfu_3s_mlops-3/scripts/get_data.py']
[2024-02-03T03:15:50.273+0400] {subprocess.py:86} INFO - Output:
[2024-02-03T03:16:50.981+0400] {subprocess.py:93} INFO - Traceback (most recent call last):
[2024-02-03T03:16:50.981+0400] {subprocess.py:93} INFO -   File "/home/reurairin/projects/urfu/urfu_3s_mlops-3/env/lib/python3.10/site-packages/urllib3/connection.py", line 174, in _new_conn
[2024-02-03T03:16:50.981+0400] {subprocess.py:93} INFO -     conn = connection.create_connection(
[2024-02-03T03:16:50.981+0400] {subprocess.py:93} INFO -   File "/home/reurairin/projects/urfu/urfu_3s_mlops-3/env/lib/python3.10/site-packages/urllib3/util/connection.py", line 95, in create_connection
[2024-02-03T03:16:50.981+0400] {subprocess.py:93} INFO -     raise err
[2024-02-03T03:16:50.981+0400] {subprocess.py:93} INFO -   File "/home/reurairin/projects/urfu/urfu_3s_mlops-3/env/lib/python3.10/site-packages/urllib3/util/connection.py", line 85, in create_connection
[2024-02-03T03:16:50.981+0400] {subprocess.py:93} INFO -     sock.connect(sa)
[2024-02-03T03:16:50.981+0400] {subprocess.py:93} INFO - ConnectionRefusedError: [Errno 111] Connection refused
[2024-02-03T03:16:50.981+0400] {subprocess.py:93} INFO - 
[2024-02-03T03:16:50.982+0400] {subprocess.py:93} INFO - During handling of the above exception, another exception occurred:
[2024-02-03T03:16:50.982+0400] {subprocess.py:93} INFO - 
[2024-02-03T03:16:50.982+0400] {subprocess.py:93} INFO - Traceback (most recent call last):
[2024-02-03T03:16:50.982+0400] {subprocess.py:93} INFO -   File "/home/reurairin/projects/urfu/urfu_3s_mlops-3/env/lib/python3.10/site-packages/urllib3/connectionpool.py", line 715, in urlopen
[2024-02-03T03:16:50.982+0400] {subprocess.py:93} INFO -     httplib_response = self._make_request(
[2024-02-03T03:16:50.982+0400] {subprocess.py:93} INFO -   File "/home/reurairin/projects/urfu/urfu_3s_mlops-3/env/lib/python3.10/site-packages/urllib3/connectionpool.py", line 416, in _make_request
[2024-02-03T03:16:50.982+0400] {subprocess.py:93} INFO -     conn.request(method, url, **httplib_request_kw)
[2024-02-03T03:16:50.982+0400] {subprocess.py:93} INFO -   File "/home/reurairin/projects/urfu/urfu_3s_mlops-3/env/lib/python3.10/site-packages/urllib3/connection.py", line 244, in request
[2024-02-03T03:16:50.982+0400] {subprocess.py:93} INFO -     super(HTTPConnection, self).request(method, url, body=body, headers=headers)
[2024-02-03T03:16:50.982+0400] {subprocess.py:93} INFO -   File "/usr/lib/python3.10/http/client.py", line 1283, in request
[2024-02-03T03:16:50.982+0400] {subprocess.py:93} INFO -     self._send_request(method, url, body, headers, encode_chunked)
[2024-02-03T03:16:50.982+0400] {subprocess.py:93} INFO -   File "/usr/lib/python3.10/http/client.py", line 1329, in _send_request
[2024-02-03T03:16:50.982+0400] {subprocess.py:93} INFO -     self.endheaders(body, encode_chunked=encode_chunked)
[2024-02-03T03:16:50.982+0400] {subprocess.py:93} INFO -   File "/usr/lib/python3.10/http/client.py", line 1278, in endheaders
[2024-02-03T03:16:50.982+0400] {subprocess.py:93} INFO -     self._send_output(message_body, encode_chunked=encode_chunked)
[2024-02-03T03:16:50.982+0400] {subprocess.py:93} INFO -   File "/usr/lib/python3.10/http/client.py", line 1038, in _send_output
[2024-02-03T03:16:50.982+0400] {subprocess.py:93} INFO -     self.send(msg)
[2024-02-03T03:16:50.982+0400] {subprocess.py:93} INFO -   File "/usr/lib/python3.10/http/client.py", line 976, in send
[2024-02-03T03:16:50.983+0400] {subprocess.py:93} INFO -     self.connect()
[2024-02-03T03:16:50.983+0400] {subprocess.py:93} INFO -   File "/home/reurairin/projects/urfu/urfu_3s_mlops-3/env/lib/python3.10/site-packages/urllib3/connection.py", line 205, in connect
[2024-02-03T03:16:50.983+0400] {subprocess.py:93} INFO -     conn = self._new_conn()
[2024-02-03T03:16:50.983+0400] {subprocess.py:93} INFO -   File "/home/reurairin/projects/urfu/urfu_3s_mlops-3/env/lib/python3.10/site-packages/urllib3/connection.py", line 186, in _new_conn
[2024-02-03T03:16:50.983+0400] {subprocess.py:93} INFO -     raise NewConnectionError(
[2024-02-03T03:16:50.983+0400] {subprocess.py:93} INFO - urllib3.exceptions.NewConnectionError: <urllib3.connection.HTTPConnection object at 0x7f5bb03e0fa0>: Failed to establish a new connection: [Errno 111] Connection refused
[2024-02-03T03:16:50.983+0400] {subprocess.py:93} INFO - 
[2024-02-03T03:16:50.983+0400] {subprocess.py:93} INFO - During handling of the above exception, another exception occurred:
[2024-02-03T03:16:50.983+0400] {subprocess.py:93} INFO - 
[2024-02-03T03:16:50.983+0400] {subprocess.py:93} INFO - Traceback (most recent call last):
[2024-02-03T03:16:50.983+0400] {subprocess.py:93} INFO -   File "/home/reurairin/projects/urfu/urfu_3s_mlops-3/env/lib/python3.10/site-packages/requests/adapters.py", line 486, in send
[2024-02-03T03:16:50.983+0400] {subprocess.py:93} INFO -     resp = conn.urlopen(
[2024-02-03T03:16:50.983+0400] {subprocess.py:93} INFO -   File "/home/reurairin/projects/urfu/urfu_3s_mlops-3/env/lib/python3.10/site-packages/urllib3/connectionpool.py", line 827, in urlopen
[2024-02-03T03:16:50.983+0400] {subprocess.py:93} INFO -     return self.urlopen(
[2024-02-03T03:16:50.983+0400] {subprocess.py:93} INFO -   File "/home/reurairin/projects/urfu/urfu_3s_mlops-3/env/lib/python3.10/site-packages/urllib3/connectionpool.py", line 827, in urlopen
[2024-02-03T03:16:50.983+0400] {subprocess.py:93} INFO -     return self.urlopen(
[2024-02-03T03:16:50.983+0400] {subprocess.py:93} INFO -   File "/home/reurairin/projects/urfu/urfu_3s_mlops-3/env/lib/python3.10/site-packages/urllib3/connectionpool.py", line 827, in urlopen
[2024-02-03T03:16:50.983+0400] {subprocess.py:93} INFO -     return self.urlopen(
[2024-02-03T03:16:50.983+0400] {subprocess.py:93} INFO -   [Previous line repeated 2 more times]
[2024-02-03T03:16:50.984+0400] {subprocess.py:93} INFO -   File "/home/reurairin/projects/urfu/urfu_3s_mlops-3/env/lib/python3.10/site-packages/urllib3/connectionpool.py", line 799, in urlopen
[2024-02-03T03:16:50.984+0400] {subprocess.py:93} INFO -     retries = retries.increment(
[2024-02-03T03:16:50.984+0400] {subprocess.py:93} INFO -   File "/home/reurairin/projects/urfu/urfu_3s_mlops-3/env/lib/python3.10/site-packages/urllib3/util/retry.py", line 592, in increment
[2024-02-03T03:16:50.984+0400] {subprocess.py:93} INFO -     raise MaxRetryError(_pool, url, error or ResponseError(cause))
[2024-02-03T03:16:50.984+0400] {subprocess.py:93} INFO - urllib3.exceptions.MaxRetryError: HTTPConnectionPool(host='0.0.0.0', port=5000): Max retries exceeded with url: /api/2.0/mlflow/experiments/get-by-name?experiment_name=get_data (Caused by NewConnectionError('<urllib3.connection.HTTPConnection object at 0x7f5bb03e0fa0>: Failed to establish a new connection: [Errno 111] Connection refused'))
[2024-02-03T03:16:50.984+0400] {subprocess.py:93} INFO - 
[2024-02-03T03:16:50.984+0400] {subprocess.py:93} INFO - During handling of the above exception, another exception occurred:
[2024-02-03T03:16:50.984+0400] {subprocess.py:93} INFO - 
[2024-02-03T03:16:50.984+0400] {subprocess.py:93} INFO - Traceback (most recent call last):
[2024-02-03T03:16:50.984+0400] {subprocess.py:93} INFO -   File "/home/reurairin/projects/urfu/urfu_3s_mlops-3/env/lib/python3.10/site-packages/mlflow/utils/rest_utils.py", line 108, in http_request
[2024-02-03T03:16:50.984+0400] {subprocess.py:93} INFO -     return _get_http_response_with_retries(
[2024-02-03T03:16:50.984+0400] {subprocess.py:93} INFO -   File "/home/reurairin/projects/urfu/urfu_3s_mlops-3/env/lib/python3.10/site-packages/mlflow/utils/request_utils.py", line 212, in _get_http_response_with_retries
[2024-02-03T03:16:50.984+0400] {subprocess.py:93} INFO -     return session.request(method, url, allow_redirects=allow_redirects, **kwargs)
[2024-02-03T03:16:50.984+0400] {subprocess.py:93} INFO -   File "/home/reurairin/projects/urfu/urfu_3s_mlops-3/env/lib/python3.10/site-packages/requests/sessions.py", line 589, in request
[2024-02-03T03:16:50.984+0400] {subprocess.py:93} INFO -     resp = self.send(prep, **send_kwargs)
[2024-02-03T03:16:50.984+0400] {subprocess.py:93} INFO -   File "/home/reurairin/projects/urfu/urfu_3s_mlops-3/env/lib/python3.10/site-packages/requests/sessions.py", line 703, in send
[2024-02-03T03:16:50.984+0400] {subprocess.py:93} INFO -     r = adapter.send(request, **kwargs)
[2024-02-03T03:16:50.984+0400] {subprocess.py:93} INFO -   File "/home/reurairin/projects/urfu/urfu_3s_mlops-3/env/lib/python3.10/site-packages/requests/adapters.py", line 519, in send
[2024-02-03T03:16:50.984+0400] {subprocess.py:93} INFO -     raise ConnectionError(e, request=request)
[2024-02-03T03:16:50.985+0400] {subprocess.py:93} INFO - requests.exceptions.ConnectionError: HTTPConnectionPool(host='0.0.0.0', port=5000): Max retries exceeded with url: /api/2.0/mlflow/experiments/get-by-name?experiment_name=get_data (Caused by NewConnectionError('<urllib3.connection.HTTPConnection object at 0x7f5bb03e0fa0>: Failed to establish a new connection: [Errno 111] Connection refused'))
[2024-02-03T03:16:50.985+0400] {subprocess.py:93} INFO - 
[2024-02-03T03:16:50.985+0400] {subprocess.py:93} INFO - During handling of the above exception, another exception occurred:
[2024-02-03T03:16:50.985+0400] {subprocess.py:93} INFO - 
[2024-02-03T03:16:50.985+0400] {subprocess.py:93} INFO - Traceback (most recent call last):
[2024-02-03T03:16:50.985+0400] {subprocess.py:93} INFO -   File "/home/reurairin/projects/urfu/urfu_3s_mlops-3/scripts/get_data.py", line 5, in <module>
[2024-02-03T03:16:50.985+0400] {subprocess.py:93} INFO -     mlflow.set_experiment("get_data")
[2024-02-03T03:16:50.985+0400] {subprocess.py:93} INFO -   File "/home/reurairin/projects/urfu/urfu_3s_mlops-3/env/lib/python3.10/site-packages/mlflow/tracking/fluent.py", line 138, in set_experiment
[2024-02-03T03:16:50.985+0400] {subprocess.py:93} INFO -     experiment = client.get_experiment_by_name(experiment_name)
[2024-02-03T03:16:50.985+0400] {subprocess.py:93} INFO -   File "/home/reurairin/projects/urfu/urfu_3s_mlops-3/env/lib/python3.10/site-packages/mlflow/tracking/client.py", line 520, in get_experiment_by_name
[2024-02-03T03:16:50.985+0400] {subprocess.py:93} INFO -     return self._tracking_client.get_experiment_by_name(name)
[2024-02-03T03:16:50.985+0400] {subprocess.py:93} INFO -   File "/home/reurairin/projects/urfu/urfu_3s_mlops-3/env/lib/python3.10/site-packages/mlflow/tracking/_tracking_service/client.py", line 221, in get_experiment_by_name
[2024-02-03T03:16:50.985+0400] {subprocess.py:93} INFO -     return self.store.get_experiment_by_name(name)
[2024-02-03T03:16:50.985+0400] {subprocess.py:93} INFO -   File "/home/reurairin/projects/urfu/urfu_3s_mlops-3/env/lib/python3.10/site-packages/mlflow/store/tracking/rest_store.py", line 306, in get_experiment_by_name
[2024-02-03T03:16:50.985+0400] {subprocess.py:93} INFO -     response_proto = self._call_endpoint(GetExperimentByName, req_body)
[2024-02-03T03:16:50.985+0400] {subprocess.py:93} INFO -   File "/home/reurairin/projects/urfu/urfu_3s_mlops-3/env/lib/python3.10/site-packages/mlflow/store/tracking/rest_store.py", line 59, in _call_endpoint
[2024-02-03T03:16:50.985+0400] {subprocess.py:93} INFO -     return call_endpoint(self.get_host_creds(), endpoint, method, json_body, response_proto)
[2024-02-03T03:16:50.985+0400] {subprocess.py:93} INFO -   File "/home/reurairin/projects/urfu/urfu_3s_mlops-3/env/lib/python3.10/site-packages/mlflow/utils/rest_utils.py", line 216, in call_endpoint
[2024-02-03T03:16:50.985+0400] {subprocess.py:93} INFO -     response = http_request(**call_kwargs)
[2024-02-03T03:16:50.986+0400] {subprocess.py:93} INFO -   File "/home/reurairin/projects/urfu/urfu_3s_mlops-3/env/lib/python3.10/site-packages/mlflow/utils/rest_utils.py", line 130, in http_request
[2024-02-03T03:16:50.986+0400] {subprocess.py:93} INFO -     raise MlflowException(f"API request to {url} failed with exception {e}")
[2024-02-03T03:16:50.986+0400] {subprocess.py:93} INFO - mlflow.exceptions.MlflowException: API request to http://0.0.0.0:5000/api/2.0/mlflow/experiments/get-by-name failed with exception HTTPConnectionPool(host='0.0.0.0', port=5000): Max retries exceeded with url: /api/2.0/mlflow/experiments/get-by-name?experiment_name=get_data (Caused by NewConnectionError('<urllib3.connection.HTTPConnection object at 0x7f5bb03e0fa0>: Failed to establish a new connection: [Errno 111] Connection refused'))
[2024-02-03T03:16:51.085+0400] {subprocess.py:97} INFO - Command exited with return code 1
[2024-02-03T03:16:51.090+0400] {taskinstance.py:2698} ERROR - Task failed with exception
Traceback (most recent call last):
  File "/home/reurairin/projects/urfu/urfu_3s_mlops-3/env/lib/python3.10/site-packages/airflow/models/taskinstance.py", line 433, in _execute_task
    result = execute_callable(context=context, **execute_callable_kwargs)
  File "/home/reurairin/projects/urfu/urfu_3s_mlops-3/env/lib/python3.10/site-packages/airflow/operators/bash.py", line 212, in execute
    raise AirflowException(
airflow.exceptions.AirflowException: Bash command failed. The command returned a non-zero exit code 1.
[2024-02-03T03:16:51.091+0400] {taskinstance.py:1138} INFO - Marking task as FAILED. dag_id=iris_score, task_id=get_data, execution_date=20240202T230845, start_date=20240202T231550, end_date=20240202T231651
[2024-02-03T03:16:51.098+0400] {standard_task_runner.py:107} ERROR - Failed to execute job 22 for task get_data (Bash command failed. The command returned a non-zero exit code 1.; 26099)
[2024-02-03T03:16:51.123+0400] {local_task_job_runner.py:234} INFO - Task exited with return code 1
[2024-02-03T03:16:51.133+0400] {taskinstance.py:3280} INFO - 0 downstream tasks scheduled from follow-on schedule check
